[[source]]
url = "https://pypi.org/simple"
verify_ssl = true
name = "pypi"

[packages]
urllib3 = "<1.26.0"  # Newer versions seem to cause BadAuthentication errors.
cryptography = ">=2.2"
protobuf = "*"
requests = "*"
pycryptodome = "*"
tqdm = "*"
flask = "*"
waitress = "*"

[dev-packages]
pytest-cov = "*"
